<?xml version="1.0" encoding="utf-8"?>
<!-- This URDF was automatically created by SolidWorks to URDF Exporter! Originally created by Stephen Brawner (brawner@gmail.com) 
     Commit Version: 1.5.1-0-g916b5db  Build Version: 1.5.7152.31018
     For more information, please see http://wiki.ros.org/sw_urdf_exporter -->
<robot
  name="falco_01">
  <link
    name="base_link">
    <inertial>
      <origin
        xyz="-0.0079646723778371 -0.000505806570357387 0.00624800334911991"
        rpy="0 0 0" />
      <mass
        value="1.39810098051634" />
      <inertia
        ixx="0.00287251572699635"
        ixy="-2.74213577469404E-07"
        ixz="-8.49343569832154E-08"
        iyy="0.00435014322218822"
        iyz="4.03196388821346E-07"
        izz="0.00695599903318864" />
    </inertial>
    <visual>
      <origin
        xyz="0 0 0"
        rpy="0 0 0" />
      <geometry>
        <mesh
          filename="package://falco_01/meshes/base_link.STL" />
      </geometry>
      <material
        name="">
        <color
          rgba="0.698039215686274 0.698039215686274 0.698039215686274 1" />
      </material>
    </visual>
    <collision>
      <origin
        xyz="0 0 0"
        rpy="0 0 0" />
      <geometry>
        <mesh
          filename="package://falco_01/meshes/base_link.STL" />
      </geometry>
    </collision>
  </link>
  <link
    name="rotor_0">
    <inertial>
      <origin
        xyz="-7.56204057483778E-07 7.83238385607121E-07 0.0122212259151821"
        rpy="0 0 0" />
      <mass
        value="0.0391311532554172" />
      <inertia
        ixx="4.3664919976507E-06"
        ixy="-9.16573656570149E-10"
        ixz="3.03652683866686E-10"
        iyy="4.36808447394079E-06"
        iyz="-3.03718891193341E-10"
        izz="4.95434642457821E-06" />
    </inertial>
    <visual>
      <origin
        xyz="0 0 0"
        rpy="0 0 0" />
      <geometry>
        <mesh
          filename="package://falco_01/meshes/rotor_0.STL" />
      </geometry>
      <material
        name="">
        <color
          rgba="0.698039215686274 0.698039215686274 0.698039215686274 1" />
      </material>
    </visual>
    <collision>
      <origin
        xyz="0 0 0"
        rpy="0 0 0" />
      <geometry>
        <mesh
          filename="package://falco_01/meshes/rotor_0.STL" />
      </geometry>
    </collision>
  </link>
  <joint
    name="rotor_0_joint"
    type="revolute">
    <origin
      xyz="0.102 -0.1 0"
      rpy="0 0 0" />
    <parent
      link="base_link" />
    <child
      link="rotor_0" />
    <axis
      xyz="0 0 1" />
    <limit
      lower="-1e+16"
      upper="1e+16"
      effort="0"
      velocity="0" />
  </joint>
  <link
    name="rotor_1">
    <inertial>
      <origin
        xyz="-7.56204057483778E-07 7.83238385620999E-07 0.0122212259151821"
        rpy="0 0 0" />
      <mass
        value="0.0391311532554171" />
      <inertia
        ixx="4.3664919976507E-06"
        ixy="-9.16573656561483E-10"
        ixz="3.03652683866238E-10"
        iyy="4.36808447394076E-06"
        iyz="-3.03718891195656E-10"
        izz="4.95434642457819E-06" />
    </inertial>
    <visual>
      <origin
        xyz="0 0 0"
        rpy="0 0 0" />
      <geometry>
        <mesh
          filename="package://falco_01/meshes/rotor_1.STL" />
      </geometry>
      <material
        name="">
        <color
          rgba="0.698039215686274 0.698039215686274 0.698039215686274 1" />
      </material>
    </visual>
    <collision>
      <origin
        xyz="0 0 0"
        rpy="0 0 0" />
      <geometry>
        <mesh
          filename="package://falco_01/meshes/rotor_1.STL" />
      </geometry>
    </collision>
  </link>
  <joint
    name="rotor_1_joint"
    type="revolute">
    <origin
      xyz="-0.102 0.1 0"
      rpy="0 0 0" />
    <parent
      link="base_link" />
    <child
      link="rotor_1" />
    <axis
      xyz="0 0 1" />
    <limit
      lower="-1e+16"
      upper="1e+16"
      effort="0"
      velocity="0" />
  </joint>
  <link
    name="rotor_2">
    <inertial>
      <origin
        xyz="-7.391944131796E-07 -1.11177206144064E-06 0.0122230869830944"
        rpy="0 0 0" />
      <mass
        value="0.0391388431003464" />
      <inertia
        ixx="4.37377975289487E-06"
        ixy="-9.13292391054662E-10"
        ixz="3.01307684828939E-10"
        iyy="4.37304400615737E-06"
        iyz="4.43259991923215E-10"
        izz="4.96517414135909E-06" />
    </inertial>
    <visual>
      <origin
        xyz="0 0 0"
        rpy="0 0 0" />
      <geometry>
        <mesh
          filename="package://falco_01/meshes/rotor_2.STL" />
      </geometry>
      <material
        name="">
        <color
          rgba="0.698039215686274 0.698039215686274 0.698039215686274 1" />
      </material>
    </visual>
    <collision>
      <origin
        xyz="0 0 0"
        rpy="0 0 0" />
      <geometry>
        <mesh
          filename="package://falco_01/meshes/rotor_2.STL" />
      </geometry>
    </collision>
  </link>
  <joint
    name="rotor_2_joint"
    type="revolute">
    <origin
      xyz="0.102 0.1 0"
      rpy="0 0 0" />
    <parent
      link="base_link" />
    <child
      link="rotor_2" />
    <axis
      xyz="0 0 1" />
    <limit
      lower="-1e+16"
      upper="1e+16"
      effort="0"
      velocity="0" />
  </joint>
  <link
    name="rotor_3">
    <inertial>
      <origin
        xyz="-7.50284720352212E-07 -1.0979880816081E-06 0.0122230860567111"
        rpy="0 0 0" />
      <mass
        value="0.0391388392694096" />
      <inertia
        ixx="4.37378460383042E-06"
        ixy="-9.10390729192987E-10"
        ixz="3.05581671692745E-10"
        iyy="4.37303473988729E-06"
        iyz="4.37924580099471E-10"
        izz="4.96517043198933E-06" />
    </inertial>
    <visual>
      <origin
        xyz="0 0 0"
        rpy="0 0 0" />
      <geometry>
        <mesh
          filename="package://falco_01/meshes/rotor_3.STL" />
      </geometry>
      <material
        name="">
        <color
          rgba="0.698039215686274 0.698039215686274 0.698039215686274 1" />
      </material>
    </visual>
    <collision>
      <origin
        xyz="0 0 0"
        rpy="0 0 0" />
      <geometry>
        <mesh
          filename="package://falco_01/meshes/rotor_3.STL" />
      </geometry>
    </collision>
  </link>
  <joint
    name="rotor_3_joint"
    type="revolute">
    <origin
      xyz="-0.102 -0.1 0"
      rpy="0 0 0" />
    <parent
      link="base_link" />
    <child
      link="rotor_3" />
    <axis
      xyz="0 0 1" />
    <limit
      lower="-1e+16"
      upper="1e+16"
      effort="0"
      velocity="0" />
  </joint>

</robot>
